Workbook

Sheet Directions
B1: Using the Template:
A2: 1 | B2: Save this template onto your OneDrive or hard drive.
A3: 2 | B3: Rename the file with your initials (i.e., Substantial Progress Workbook_MHSP_DSC).
A4: 3 | B4: Select your grantees from the list on the "MHSP Grantees" or "SBMH Grantees" tab. You can delete or hide the ones that you do not monitor.
A5: 4 | B5: Begin at the top of the list (or wherever you want) and rename the first tab with the PR Award Number of the grantee APR that you're reviewing. For example, rename the first tab S184H220000).
A6: 5 | B6: Before entering data into the tab, right click on the tab name. Select "move or copy" and copy the worksheet. This creates a duplicate sheet.
A7: 6 | B7: Rename the duplicate sheet with the next PR Award number.
A8: 7 | B8: Repeat this "move or copy" and renaming step for all of your grantees so they each have a worksheet.
A9: 8 | B9: Using the definitions tab, review the APR and record the LETTER grades for the administrative factors in the blue boxes. The boxes that say "FALSE" should turn into a percentage when you enter the grade.
A10: 9 | B10: For the GPRA measures, please enter a "1" in the blue box if the grantee meets the threshold for the year of review. Please enter "0" in the blue box if the grantee does not meet the expectation. This should tally into a percentage in the last row.
A11: 10 | B11: When you have completed your review, you can go onto the next one.
A12: 11 | B12: When you are completely done reviewing your grantees APRs, please share your worksheet to your supervisor for aggregation!

Sheet Definitions
A1: ADMIN FACTORS
B2: Financial, LAB >70%
A3: A | B3: No LAB OR LAB but funds are encumbered, just not drawn down because of accounting/fiscal
A4: B | B4: Has LAB but making progress, no concerns, plans for funds
A5: C | B5: Has LAB but w less clear explanation or plans, or still has LAB from previous project years
A6: F | B6: Large LAB, no plans, large LABs from previous project years
B8: Financial, Excessive Drawdowns
A9: A | B9: No ED
A10: B | B10: Explained and paid back, no concerns
A11: C | B11: Once, not paid back in timely fashion
A12: F | B12: More than once, all funds or large amount, not paid back timely
B14: Performance, PD changes or staffing turnover
A15: A | B15: No PD changes or normal shifting of staff as project starts or proceeds
A16: B | B16: Unclear staffing or some concern
A17: C | B17: More than 1 PD or staff turnover
A18: F | B18: High, more than 2 PDs
B20: Performance, other
A21: A | B21: No concerns, all components are included or quickly provided
A22: B | B22: Some questions about performance or pace of project, lack of clarity on or concern about at least one aspect of performance, one component of APR missing (please specify issues of concern in Notes column, including missing elements from APR)
A23: C | B23: Inconsistent contact/response time, frequent changes to plan, late reports, unclear partnerships, lack of clarity on or concern about a few aspects of performance but they are making progress, more than one component of APR missing (please specify issues of concern in Notes column, including missing elements from APR)
A24: F | B24: Grantee is unresponsive or slow to respond, late APR or IPR, frequent changes to plan, goals are unclear, unable to identify partners or challenges with partners, adding new partners, APR missing or submitted late or significant pieces are not included (please specify issues of concern in Notes column, including missing elements from APR)
B26: Internal controls (could include financial adjustments, lack of drawdowns)
A27: A | B27: No concerns
A28: B | B28: Minimal concerns noted but not impeding progress
A29: C | B29: Questionable internal controls
A30: F | B30: Seeming lack of internal controls (questionable PD, financial management, no AR, etc)
B32: Conditions
A33: A | B33: Conditions met/no conditions
A34: B | B34: Conditions met/no conditions
A35: C | B35: Conditions not met but working towards
A36: F | B36: Conditions not met in timely fashion
A39: GPRA MEASURES
A40: 1= YES | B40: GPRA 1: HIRED
A41: 0= NO | B41: Y1: 20-25% of target
B42: Y2: 25-50% of target
B43: Y3: 50-70% of target
B44: Y4: 70-90% of target
B45: Y5: 90-100% of target
B47: GPRA 2: Retained
B48: Y1: 20-25% of target
...

Sheet SBMH Grantees
D1: Y1 | E1: Y2 | F1: Y3 | G1: Y4 | H1: Y5
A2: S184H220021 | B2: Northfield State Department of Education | C2: OK
A3: S184H220197 | B3: Lakewood Unified School District | C3: IN | E3: 33
A4: S184H220199 | B4: Riverside City Schools | C4: ME
A5: S184H220041 | B5: Clearwater County Schools | C5: NJ
A6: S184H220067 | B6: Summit Hills School District | C6: IL
A7: S184H220138 | B7: Maplewood Joint Unified School District | C7: DC
A8: S184H220259 | B8: Brookfield City Schools | C8: NC
A9: S184H220120 | B9: Crestview County School District | C9: RI
A10: S184H220101 | B10: Pinehurst Independent School District | C10: VA
A11: S184H220184 | B11: Elmwood State Department of Education | C11: TN
A12: S184H220074 | B12: Fairview Unified School District | C12: WA
A13: S184H220237 | B13: Greenfield Community School District | C13: CA
A14: S184H220028 | B14: Hillside County Schools | C14: KY
A15: S184H220045 | B15: Ironwood Public Schools | C15: TN
... A49: S184H220177 | B49: Quarryhill City Schools | C49: OK
A50: S184H220220 | B50: Ravenwood County School District | C50: WI | E50: 74
A51: S184H220095 | B51: Saltmarsh Public Schools | C51: NC
A52: S184H220142 | B52: Thornfield Unified School District | C52: CO
A53: S184H220143 | B53: Underhill City Schools | C53: MS
A54: S184H220044 | B54: Valewood County School District | C54: NY
A55: S184H220088 | B55: Whitmore Public Schools | C55: OK
A56: S184H220149 | B56: Foxgate Unified School District | C56: TN
A57: S184H220111 | B57: Coldwater City Schools | C57: OH
A58: S184H220124 | B58: Driftwood County School District | C58: CA
A59: S184H220232 | B59: Emberfield Public Schools | C59: IL
A60: S184H220183 | B60: Ferndale Unified School District | C60: CA
A61: S184H220076 | B61: Goldcrest City Schools | C61: IL
A62: S184H220121 | B62: Hawthorne County School District | C62: CA
... A105: S184H230201 | B105: Para Los Ninos | C105: CA

Sheet S184H220
A1: Measure | B1: EXAMPLE | D1: Y1 | F1: Y2 | H1: Y3 | J1: Y4 | L1: Y5 | N1: Notes
A2: [Note redacted for anonymization]
A3: Financial, LAB >70% | B3: A | C3: =IF(B3="A",1,IF(B3="B",0.75,IF(B3="C",0.5,IF(B3="F",0)))) | E3: =IF(D3="A",1,IF(D3="B",0.75,IF(D3="C",0.5,IF(D3="F",0)))) | G3: =IF(F3="A",1,IF(F3="B",0.75,IF(F3="C",0.5,IF(F3="F",0)))) | I3: =IF(H3="A",1,IF(H3="B",0.75,IF(H3="C",0.5,IF(H3="F",0)))) | K3: =IF(J3="A",1,IF(J3="B",0.75,IF(J3="C",0.5,IF(J3="F",0)))) | M3: =IF(L3="A",1,IF(L3="B",0.75,IF(L3="C",0.5,IF(L3="F",0))))
A5: Financial, Excessive Drawdowns | B5: F | C5: =IF(B5="A",1,IF(B5="B",0.75,IF(B5="C",0.5,IF(B5="F",0)))) | E5: =IF(D5="A",1,IF(D5="B",0.75,IF(D5="C",0.5,IF(D5="F",0)))) | G5: =IF(F5="A",1,IF(F5="B",0.75,IF(F5="C",0.5,IF(F5="F",0)))) | I5: =IF(H5="A",1,IF(H5="B",0.75,IF(H5="C",0.5,IF(H5="F",0)))) | K5: =IF(J5="A",1,IF(J5="B",0.75,IF(J5="C",0.5,IF(J5="F",0)))) | M5: =IF(L5="A",1,IF(L5="B",0.75,IF(L5="C",0.5,IF(L5="F",0))))
A7: Performance, PD changes or staffing turnover | B7: A | C7: =IF(B7="A",1,IF(B7="B",0.75,IF(B7="C",0.5,IF(B7="F",0)))) | E7: =IF(D7="A",1,IF(D7="B",0.75,IF(D7="C",0.5,IF(D7="F",0)))) | G7: =IF(F7="A",1,IF(F7="B",0.75,IF(F7="C",0.5,IF(F7="F",0)))) | I7: =IF(H7="A",1,IF(H7="B",0.75,IF(H7="C",0.5,IF(H7="F",0)))) | K7: =IF(J7="A",1,IF(J7="B",0.75,IF(J7="C",0.5,IF(J7="F",0)))) | M7: =IF(L7="A",1,IF(L7="B",0.75,IF(L7="C",0.5,IF(L7="F",0))))
A9: Performance, other | B9: B | C9: =IF(B9="A",1,IF(B9="B",0.75,IF(B9="C",0.5,IF(B9="F",0)))) | E9: =IF(D9="A",1,IF(D9="B",0.75,IF(D9="C",0.5,IF(D9="F",0)))) | G9: =IF(F9="A",1,IF(F9="B",0.75,IF(F9="C",0.5,IF(F9="F",0)))) | I9: =IF(H9="A",1,IF(H9="B",0.75,IF(H9="C",0.5,IF(H9="F",0)))) | K9: =IF(J9="A",1,IF(J9="B",0.75,IF(J9="C",0.5,IF(J9="F",0)))) | M9: =IF(L9="A",1,IF(L9="B",0.75,IF(L9="C",0.5,IF(L9="F",0))))
A11: Internal controls (could include financial adjustments, lack of drawdowns) | B11: C | C11: =IF(B11="A",1,IF(B11="B",0.75,IF(B11="C",0.5,IF(B11="F",0)))) | E11: =IF(D11="A",1,IF(D11="B",0.75,IF(D11="C",0.5,IF(D11="F",0)))) | G11: =IF(F11="A",1,IF(F11="B",0.75,IF(F11="C",0.5,IF(F11="F",0)))) | I11: =IF(H11="A",1,IF(H11="B",0.75,IF(H11="C",0.5,IF(H11="F",0)))) | K11: =IF(J11="A",1,IF(J11="B",0.75,IF(J11="C",0.5,IF(J11="F",0)))) | M11: =IF(L11="A",1,IF(L11="B",0.75,IF(L11="C",0.5,IF(L11="F",0))))
A13: Conditions | B13: A | C13: =IF(B13="A",1,IF(B13="B",0.75,IF(B13="C",0.5,IF(B13="F",0)))) | E13: =IF(D13="A",1,IF(D13="B",0.75,IF(D13="C",0.5,IF(D13="F",0)))) | G13: =IF(F13="A",1,IF(F13="B",0.75,IF(F13="C",0.5,IF(F13="F",0)))) | I13: =IF(H13="A",1,IF(H13="B",0.75,IF(H13="C",0.5,IF(H13="F",0)))) | K13: =IF(J13="A",1,IF(J13="B",0.75,IF(J13="C",0.5,IF(J13="F",0)))) | M13: =IF(L13="A",1,IF(L13="B",0.75,IF(L13="C",0.5,IF(L13="F",0))))
A15: TOTAL SCORE ADMINISTRATIVE | C15: =SUM(C3*0.1, C5*0.1, C7*0.1, C9*0.5,C11*0.1,C13*0.1) | E15: =SUM(E3*0.1, E5*0.1, E7*0.1, E9*0.55,E11*0.1,E13*0.05) | G15: =SUM(G3*0.1, G5*0.1, G7*0.1, G9*0.55,G11*0.1,G13*0.05) | I15: =SUM(I3*0.1, I5*0.1, I7*0.1, I9*0.55,I11*0.1,I13*0.05) | K15: =SUM(K3*0.1, K5*0.1, K7*0.1, K9*0.55,K11*0.1,K13*0.05) | M15: =SUM(M3*0.2, M5*0.1, M7*0.1, M9*0.55,M11*0.05)
A17: GPRA MEASURES
A18: GPRA 1: Hired
A19: GPRA 2: Retained
A20: GPRA 3: Ratio
A21: GPRA 4: Attrition
A22: [Note redacted for anonymization]
A23: TOTAL SCORE GPRA | B23: =SUM(B18*0.4, B19*0.2, B20*0.1, B21*0.2, B22*0.1) | E23: =-SUM(E18*0.4, E19*0.2, E20*0.1, E21*0.2, E22*0.1) | G23: =-SUM(G18*0.4, G19*0.2, G20*0.1, G21*0.2, G22*0.1) | I23: =-SUM(I18*0.4, I19*0.2, I20*0.1, I21*0.2, I22*0.1) | K23: =-SUM(K18*0.4, K19*0.2, K20*0.1, K21*0.2, K22*0.1) | M23: =-SUM(M18*0.4, M19*0.2, M20*0.1, M21*0.2, M22*0.1)
A26: TOTAL SCORES | C26: =SUM(C15*0.6, B23*0.4) | E26: =SUM(E15*0.6, E23*0.4) | G26: =SUM(G15*0.6, G23*0.4) | I26: =SUM(I15*0.5, I23*0.5) | K26: =SUM(K15*0.4, K23*0.6) | M26: =SUM(M15*0.3, M23*0.7)

Sheet S184H2200 (2)
A1: Measure | B1: EXAMPLE | D1: Y1 | F1: Y2 | H1: Y3 | J1: Y4 | L1: Y5 | N1: Notes
A2: [Note redacted for anonymization]
A3: Financial, LAB >70% | B3: A | C3: =IF(B3="A",1,IF(B3="B",0.75,IF(B3="C",0.5,IF(B3="F",0)))) | E3: =IF(D3="A",1,IF(D3="B",0.75,IF(D3="C",0.5,IF(D3="F",0)))) | G3: =IF(F3="A",1,IF(F3="B",0.75,IF(F3="C",0.5,IF(F3="F",0)))) | I3: =IF(H3="A",1,IF(H3="B",0.75,IF(H3="C",0.5,IF(H3="F",0)))) | K3: =IF(J3="A",1,IF(J3="B",0.75,IF(J3="C",0.5,IF(J3="F",0)))) | M3: =IF(L3="A",1,IF(L3="B",0.75,IF(L3="C",0.5,IF(L3="F",0))))
A5: Financial, Excessive Drawdowns | B5: F | C5: =IF(B5="A",1,IF(B5="B",0.75,IF(B5="C",0.5,IF(B5="F",0)))) | E5: =IF(D5="A",1,IF(D5="B",0.75,IF(D5="C",0.5,IF(D5="F",0)))) | G5: =IF(F5="A",1,IF(F5="B",0.75,IF(F5="C",0.5,IF(F5="F",0)))) | I5: =IF(H5="A",1,IF(H5="B",0.75,IF(H5="C",0.5,IF(H5="F",0)))) | K5: =IF(J5="A",1,IF(J5="B",0.75,IF(J5="C",0.5,IF(J5="F",0)))) | M5: =IF(L5="A",1,IF(L5="B",0.75,IF(L5="C",0.5,IF(L5="F",0))))
A7: Performance, PD changes or staffing turnover | B7: A | C7: =IF(B7="A",1,IF(B7="B",0.75,IF(B7="C",0.5,IF(B7="F",0)))) | E7: =IF(D7="A",1,IF(D7="B",0.75,IF(D7="C",0.5,IF(D7="F",0)))) | G7: =IF(F7="A",1,IF(F7="B",0.75,IF(F7="C",0.5,IF(F7="F",0)))) | I7: =IF(H7="A",1,IF(H7="B",0.75,IF(H7="C",0.5,IF(H7="F",0)))) | K7: =IF(J7="A",1,IF(J7="B",0.75,IF(J7="C",0.5,IF(J7="F",0)))) | M7: =IF(L7="A",1,IF(L7="B",0.75,IF(L7="C",0.5,IF(L7="F",0))))
A9: Performance, other | B9: B | C9: =IF(B9="A",1,IF(B9="B",0.75,IF(B9="C",0.5,IF(B9="F",0)))) | E9: =IF(D9="A",1,IF(D9="B",0.75,IF(D9="C",0.5,IF(D9="F",0)))) | G9: =IF(F9="A",1,IF(F9="B",0.75,IF(F9="C",0.5,IF(F9="F",0)))) | I9: =IF(H9="A",1,IF(H9="B",0.75,IF(H9="C",0.5,IF(H9="F",0)))) | K9: =IF(J9="A",1,IF(J9="B",0.75,IF(J9="C",0.5,IF(J9="F",0)))) | M9: =IF(L9="A",1,IF(L9="B",0.75,IF(L9="C",0.5,IF(L9="F",0))))
A11: Internal controls (could include financial adjustments, lack of drawdowns) | B11: C | C11: =IF(B11="A",1,IF(B11="B",0.75,IF(B11="C",0.5,IF(B11="F",0)))) | E11: =IF(D11="A",1,IF(D11="B",0.75,IF(D11="C",0.5,IF(D11="F",0)))) | G11: =IF(F11="A",1,IF(F11="B",0.75,IF(F11="C",0.5,IF(F11="F",0)))) | I11: =IF(H11="A",1,IF(H11="B",0.75,IF(H11="C",0.5,IF(H11="F",0)))) | K11: =IF(J11="A",1,IF(J11="B",0.75,IF(J11="C",0.5,IF(J11="F",0)))) | M11: =IF(L11="A",1,IF(L11="B",0.75,IF(L11="C",0.5,IF(L11="F",0))))
A13: Conditions | B13: A | C13: =IF(B13="A",1,IF(B13="B",0.75,IF(B13="C",0.5,IF(B13="F",0)))) | E13: =IF(D13="A",1,IF(D13="B",0.75,IF(D13="C",0.5,IF(D13="F",0)))) | G13: =IF(F13="A",1,IF(F13="B",0.75,IF(F13="C",0.5,IF(F13="F",0)))) | I13: =IF(H13="A",1,IF(H13="B",0.75,IF(H13="C",0.5,IF(H13="F",0)))) | K13: =IF(J13="A",1,IF(J13="B",0.75,IF(J13="C",0.5,IF(J13="F",0)))) | M13: =IF(L13="A",1,IF(L13="B",0.75,IF(L13="C",0.5,IF(L13="F",0))))
A15: TOTAL SCORE ADMINISTRATIVE | C15: =SUM(C3*0.1, C5*0.1, C7*0.1, C9*0.5,C11*0.1,C13*0.1) | E15: =SUM(E3*0.1, E5*0.1, E7*0.1, E9*0.55,E11*0.1,E13*0.05) | G15: =SUM(G3*0.1, G5*0.1, G7*0.1, G9*0.55,G11*0.1,G13*0.05) | I15: =SUM(I3*0.1, I5*0.1, I7*0.1, I9*0.55,I11*0.1,I13*0.05) | K15: =SUM(K3*0.1, K5*0.1, K7*0.1, K9*0.55,K11*0.1,K13*0.05) | M15: =SUM(M3*0.2, M5*0.1, M7*0.1, M9*0.55,M11*0.05)
A17: GPRA MEASURES
A18: GPRA 1: Hired
A19: GPRA 2: Retained
A20: GPRA 3: Ratio
A21: GPRA 4: Attrition
A22: [Note redacted for anonymization]
A23: TOTAL SCORE GPRA | B23: =SUM(B18*0.4, B19*0.2, B20*0.1, B21*0.2, B22*0.1) | E23: =-SUM(E18*0.4, E19*0.2, E20*0.1, E21*0.2, E22*0.1) | G23: =-SUM(G18*0.4, G19*0.2, G20*0.1, G21*0.2, G22*0.1) | I23: =-SUM(I18*0.4, I19*0.2, I20*0.1, I21*0.2, I22*0.1) | K23: =-SUM(K18*0.4, K19*0.2, K20*0.1, K21*0.2, K22*0.1) | M23: =-SUM(M18*0.4, M19*0.2, M20*0.1, M21*0.2, M22*0.1)
A26: TOTAL SCORES | C26: =SUM(C15*0.6, B23*0.4) | E26: =SUM(E15*0.6, E23*0.4) | G26: =SUM(G15*0.6, G23*0.4) | I26: =SUM(I15*0.5, I23*0.5) | K26: =SUM(K15*0.4, K23*0.6) | M26: =SUM(M15*0.3, M23*0.7)

Sheet S184H2200
A1: Measure | B1: EXAMPLE | D1: Y1 | F1: Y2 | H1: Y3 | J1: Y4 | L1: Y5 | N1: Notes
A2: [Note redacted for anonymization]
A3: Financial, LAB >70% | B3: A | C3: =IF(B3="A",1,IF(B3="B",0.75,IF(B3="C",0.5,IF(B3="F",0)))) | E3: =IF(D3="A",1,IF(D3="B",0.75,IF(D3="C",0.5,IF(D3="F",0)))) | G3: =IF(F3="A",1,IF(F3="B",0.75,IF(F3="C",0.5,IF(F3="F",0)))) | I3: =IF(H3="A",1,IF(H3="B",0.75,IF(H3="C",0.5,IF(H3="F",0)))) | K3: =IF(J3="A",1,IF(J3="B",0.75,IF(J3="C",0.5,IF(J3="F",0)))) | M3: =IF(L3="A",1,IF(L3="B",0.75,IF(L3="C",0.5,IF(L3="F",0))))
A5: Financial, Excessive Drawdowns | B5: F | C5: =IF(B5="A",1,IF(B5="B",0.75,IF(B5="C",0.5,IF(B5="F",0)))) | E5: =IF(D5="A",1,IF(D5="B",0.75,IF(D5="C",0.5,IF(D5="F",0)))) | G5: =IF(F5="A",1,IF(F5="B",0.75,IF(F5="C",0.5,IF(F5="F",0)))) | I5: =IF(H5="A",1,IF(H5="B",0.75,IF(H5="C",0.5,IF(H5="F",0)))) | K5: =IF(J5="A",1,IF(J5="B",0.75,IF(J5="C",0.5,IF(J5="F",0)))) | M5: =IF(L5="A",1,IF(L5="B",0.75,IF(L5="C",0.5,IF(L5="F",0))))
A7: Performance, PD changes or staffing turnover | B7: A | C7: =IF(B7="A",1,IF(B7="B",0.75,IF(B7="C",0.5,IF(B7="F",0)))) | E7: =IF(D7="A",1,IF(D7="B",0.75,IF(D7="C",0.5,IF(D7="F",0)))) | G7: =IF(F7="A",1,IF(F7="B",0.75,IF(F7="C",0.5,IF(F7="F",0)))) | I7: =IF(H7="A",1,IF(H7="B",0.75,IF(H7="C",0.5,IF(H7="F",0)))) | K7: =IF(J7="A",1,IF(J7="B",0.75,IF(J7="C",0.5,IF(J7="F",0)))) | M7: =IF(L7="A",1,IF(L7="B",0.75,IF(L7="C",0.5,IF(L7="F",0))))
A9: Performance, other | B9: B | C9: =IF(B9="A",1,IF(B9="B",0.75,IF(B9="C",0.5,IF(B9="F",0)))) | E9: =IF(D9="A",1,IF(D9="B",0.75,IF(D9="C",0.5,IF(D9="F",0)))) | G9: =IF(F9="A",1,IF(F9="B",0.75,IF(F9="C",0.5,IF(F9="F",0)))) | I9: =IF(H9="A",1,IF(H9="B",0.75,IF(H9="C",0.5,IF(H9="F",0)))) | K9: =IF(J9="A",1,IF(J9="B",0.75,IF(J9="C",0.5,IF(J9="F",0)))) | M9: =IF(L9="A",1,IF(L9="B",0.75,IF(L9="C",0.5,IF(L9="F",0))))
A11: Internal controls (could include financial adjustments, lack of drawdowns) | B11: C | C11: =IF(B11="A",1,IF(B11="B",0.75,IF(B11="C",0.5,IF(B11="F",0)))) | E11: =IF(D11="A",1,IF(D11="B",0.75,IF(D11="C",0.5,IF(D11="F",0)))) | G11: =IF(F11="A",1,IF(F11="B",0.75,IF(F11="C",0.5,IF(F11="F",0)))) | I11: =IF(H11="A",1,IF(H11="B",0.75,IF(H11="C",0.5,IF(H11="F",0)))) | K11: =IF(J11="A",1,IF(J11="B",0.75,IF(J11="C",0.5,IF(J11="F",0)))) | M11: =IF(L11="A",1,IF(L11="B",0.75,IF(L11="C",0.5,IF(L11="F",0))))
A13: Conditions | B13: A | C13: =IF(B13="A",1,IF(B13="B",0.75,IF(B13="C",0.5,IF(B13="F",0)))) | E13: =IF(D13="A",1,IF(D13="B",0.75,IF(D13="C",0.5,IF(D13="F",0)))) | G13: =IF(F13="A",1,IF(F13="B",0.75,IF(F13="C",0.5,IF(F13="F",0)))) | I13: =IF(H13="A",1,IF(H13="B",0.75,IF(H13="C",0.5,IF(H13="F",0)))) | K13: =IF(J13="A",1,IF(J13="B",0.75,IF(J13="C",0.5,IF(J13="F",0)))) | M13: =IF(L13="A",1,IF(L13="B",0.75,IF(L13="C",0.5,IF(L13="F",0))))
A15: TOTAL SCORE ADMINISTRATIVE | C15: =SUM(C3*0.1, C5*0.1, C7*0.1, C9*0.5,C11*0.1,C13*0.1) | E15: =SUM(E3*0.1, E5*0.1, E7*0.1, E9*0.55,E11*0.1,E13*0.05) | G15: =SUM(G3*0.1, G5*0.1, G7*0.1, G9*0.55,G11*0.1,G13*0.05) | I15: =SUM(I3*0.1, I5*0.1, I7*0.1, I9*0.55,I11*0.1,I13*0.05) | K15: =SUM(K3*0.1, K5*0.1, K7*0.1, K9*0.55,K11*0.1,K13*0.05) | M15: =SUM(M3*0.2, M5*0.1, M7*0.1, M9*0.55,M11*0.05)
A17: GPRA MEASURES
A18: GPRA 1: Hired
A19: GPRA 2: Retained
A20: GPRA 3: Ratio
A21: GPRA 4: Attrition
A22: [Note redacted for anonymization]
A23: TOTAL SCORE GPRA | B23: =SUM(B18*0.4, B19*0.2, B20*0.1, B21*0.2, B22*0.1) | E23: =-SUM(E18*0.4, E19*0.2, E20*0.1, E21*0.2, E22*0.1) | G23: =-SUM(G18*0.4, G19*0.2, G20*0.1, G21*0.2, G22*0.1) | I23: =-SUM(I18*0.4, I19*0.2, I20*0.1, I21*0.2, I22*0.1) | K23: =-SUM(K18*0.4, K19*0.2, K20*0.1, K21*0.2, K22*0.1) | M23: =-SUM(M18*0.4, M19*0.2, M20*0.1, M21*0.2, M22*0.1)
A26: TOTAL SCORES | C26: =SUM(C15*0.6, B23*0.4) | E26: =SUM(E15*0.6, E23*0.4) | G26: =SUM(G15*0.6, G23*0.4) | I26: =SUM(I15*0.5, I23*0.5) | K26: =SUM(K15*0.4, K23*0.6) | M26: =SUM(M15*0.3, M23*0.7)

Sheet Sheet8

Sheet Administrative Factors
B1: Measure | C1: EXAMPLE | E1: Y1 | G1: Y2 | I1: Y3 | K1: Y4 | M1: Y5 | O1: Notes
B2: Financial, LAB >70% | C2: A | D2: =IF(C2="A",1,IF(C2="B",0.75,IF(C2="C",0.5,IF(C2="F",0)))) | F2: =IF(E2="A",1,IF(E2="B",0.75,IF(E2="C",0.5,IF(E2="F",0)))) | H2: =IF(G2="A",1,IF(G2="B",0.75,IF(G2="C",0.5,IF(G2="F",0)))) | J2: =IF(I2="A",1,IF(I2="B",0.75,IF(I2="C",0.5,IF(I2="F",0)))) | L2: =IF(K2="A",1,IF(K2="B",0.75,IF(K2="C",0.5,IF(K2="F",0)))) | N2: =IF(M2="A",1,IF(M2="B",0.75,IF(M2="C",0.5,IF(M2="F",0))))
A3: A | B3: No LAB
A4: B | B4: >=2 quarters, making progress, no concerns
A5: C | B5: >= 3 quarters w explanation
A6: F | B6: All 4 quarters, 70-100%
B9: Financial, Excessive Drawdowns | C9: F | D9: =IF(C9="A",1,IF(C9="B",0.75,IF(C9="C",0.5,IF(C9="F",0)))) | F9: =IF(E9="A",1,IF(E9="B",0.75,IF(E9="C",0.5,IF(E9="F",0)))) | H9: =IF(G9="A",1,IF(G9="B",0.75,IF(G9="C",0.5,IF(G9="F",0)))) | J9: =IF(I9="A",1,IF(I9="B",0.75,IF(I9="C",0.5,IF(I9="F",0)))) | L9: =IF(K9="A",1,IF(K9="B",0.75,IF(K9="C",0.5,IF(K9="F",0)))) | N9: =IF(M9="A",1,IF(M9="B",0.75,IF(M9="C",0.5,IF(M9="F",0))))
A10: A | B10: No ED
A11: B | B11: Explained and paid back, no concerns
A12: C | B12: Once, not paid back in timely fashion
A13: F | B13: More than once, all funds or large amount, not paid back timely
B15: Performance, PD changes or staffing turnover | C15: B | D15: =IF(C15="A",1,IF(C15="B",0.75,IF(C15="C",0.5,IF(C15="F",0)))) | F15: =IF(E15="A",1,IF(E15="B",0.75,IF(E15="C",0.5,IF(E15="F",0)))) | H15: =IF(G15="A",1,IF(G15="B",0.75,IF(G15="C",0.5,IF(G15="F",0)))) | J15: =IF(I15="A",1,IF(I15="B",0.75,IF(I15="C",0.5,IF(I15="F",0)))) | L15: =IF(K15="A",1,IF(K15="B",0.75,IF(K15="C",0.5,IF(K15="F",0)))) | N15: =IF(M15="A",1,IF(M15="B",0.75,IF(M15="C",0.5,IF(M15="F",0))))
A16: A | B16: No PD changes or normal shifting of staff as project starts or proceeds
A17: B | B17: Unclear staffing or some concern
A18: C | B18: More than 1 PD or staff turnover
A19: F | B19: High, more than 2 PDs
B21: Performance, other | C21: B | D21: =IF(C21="A",1,IF(C21="B",0.75,IF(C21="C",0.5,IF(C21="F",0)))) | F21: =IF(E21="A",1,IF(E21="B",0.75,IF(E21="C",0.5,IF(E21="F",0)))) | H21: =IF(G21="A",1,IF(G21="B",0.75,IF(G21="C",0.5,IF(G21="F",0)))) | J21: =IF(I21="A",1,IF(I21="B",0.75,IF(I21="C",0.5,IF(I21="F",0)))) | L21: =IF(K21="A",1,IF(K21="B",0.75,IF(K21="C",0.5,IF(K21="F",0)))) | N21: =IF(M21="A",1,IF(M21="B",0.75,IF(M21="C",0.5,IF(M21="F",0))))
A22: A | B22: No concerns
A23: B | B23: Some questions about performance or pace of project, lack of clarity on or concern about at least one aspect of performance
A24: C | B24: Inconsistent contact/response time, frequent changes to plan, late reports, unclear partnerships, lack of clarity on or concern about a few aspects of performance but they are making progress
A25: F | B25: Grantee is unresponsive or slow to respond, late APR or IPR, frequent changes to plan, goals are unclear, unable to identify partners or challenges with partners, adding new partners
B27: Internal controls (could include financial adjustments, lack of drawdowns) | C27: C | D27: =IF(C27="A",1,IF(C27="B",0.75,IF(C27="C",0.5,IF(C27="F",0)))) | F27: =IF(E27="A",1,IF(E27="B",0.75,IF(E27="C",0.5,IF(E27="F",0)))) | H27: =IF(G27="A",1,IF(G27="B",0.75,IF(G27="C",0.5,IF(G27="F",0)))) | J27: =IF(I27="A",1,IF(I27="B",0.75,IF(I27="C",0.5,IF(I27="F",0)))) | L27: =IF(K27="A",1,IF(K27="B",0.75,IF(K27="C",0.5,IF(K27="F",0)))) | N27: =IF(M27="A",1,IF(M27="B",0.75,IF(M27="C",0.5,IF(M27="F",0))))
A28: A | B28: No concerns
A29: B | B29: Minimal concerns noted but not impeding progress
A30: C | B30: Questionable internal controls
A31: F | B31: Seeming lack of internal controls (questionable PD, financial management, no AR, etc)
B33: Conditions | C33: A | D33: =IF(C33="A",1,IF(C33="B",0.75,IF(C33="C",0.5,IF(C33="F",0)))) | F33: =IF(E33="A",1,IF(E33="B",0.75,IF(E33="C",0.5,IF(E33="F",0)))) | H33: =IF(G33="A",1,IF(G33="B",0.75,IF(G33="C",0.5,IF(G33="F",0)))) | J33: =IF(I33="A",1,IF(I33="B",0.75,IF(I33="C",0.5,IF(I33="F",0)))) | L33: =IF(K33="A",1,IF(K33="B",0.75,IF(K33="C",0.5,IF(K33="F",0)))) | N33: =IF(M33="A",1,IF(M33="B",0.75,IF(M33="C",0.5,IF(M33="F",0))))
A34: A | B34: Conditions met/no conditions
A35: B | B35: Conditions met/no conditions
A36: C | B36: Conditions not met but working towards
A37: F | B37: Conditions not met in timely fashion
B39: TOTAL SCORE | D39: =SUM(D2*0.1, D9*0.1, D15*0.1, D21*0.5,D27*0.1,D33*0.1) | F39: =SUM(F2*0.1, F9*0.1, F15*0.1, F21*0.5,F27*0.1,F33*0.1) | H39: =SUM(H2*0.1, H9*0.1, H15*0.1, H21*0.5,H27*0.1,H33*0.1) | J39: =SUM(J2*0.1, J9*0.1, J15*0.1, J21*0.5,J27*0.1,J33*0.1) | L39: =SUM(L2*0.1, L9*0.1, L15*0.1, L21*0.5,L27*0.1,L33*0.1) | N39: =SUM(N2*0.2, N9*0.1, N15*0.1, N21*0.5,N27*0.1)

Sheet SBMH- GPRA
A1: GPRA Measures | B1: Example | C1: Y1 | D1: Y2 | E1: Y3 | F1: Y4 | G1: Y5
A2: 1=YES, 0=NO | C2: Score
A4: GPRA 1: HIRED | B4: 1
A5: Y1: 20-25% of target
A6: Y2: 25-50% of target
A7: Y3: 50-70% of target
A8: Y4: 70-90% of target
A9: Y5: 90-100% of target
A11: GPRA 2: Retained | B11: 1
A12: Y1: 20-25% of target
A13: Y2: 25-50% of target
A14: Y3: 50-70% of target
A15: Y4: 70-90% of target
A16: Y5: 90-100% of target
A18: GPRA 3: Ratio | B18: 1
A19: Y1: Ratio is improving
A20: Y2: Ratio improved or stable
A21: Y3: Ratio improved or stable
A22: Y4: Ratio improved or stable
A23: Y5: Ratio improved or stable
A25: GPRA 4: Attrition | B25: 0
A26: Y1: 10% of target
A27: Y2: 11-25% of target
A28: Y3: 26-50% of target
A29: Y4: 51-75% of target
A30: Y5: 76-100% of target
A32: GPRA 5: Students Served | B32: 1
A33: Y1: Serving students
A34: Y2: Number increased or stable
A35: Y3: Number increased or stable
A36: Y4: Number increased or stable
A37: Y5: Number increased or stable
B38: =SUM(B4*0.4,B11*0.3,B18*0.05,B25*0.2,B32*0.05) | C38: =SUM(C4*0.4,C11*0.3,C18*0.05,C25*0.2,C32*0.05) | D38: =SUM(D4*0.5,D11*0.3,D18*0.05,D25*0.1,D32*0.05) | E38: =SUM(E4*0.5,E11*0.3,E18*0.05,E25*0.1,E32*0.05) | F38: =SUM(F4*0.5,F11*0.3,F18*0.05,F25*0.1,F32*0.05) | G38: =SUM(G4*0.5,G11*0.3,G18*0.05,G25*0.1,G32*0.05)

Sheet MHSP - GPRA
A1: GPRA Measures | B1: Example | C1: Y1 | D1: Y2 | E1: Y3 | F1: Y4 | G1: Y5
A2: 1=YES, 0=NO | C2: Score
A4: GPRA 1: TRAINING
A5: GPRA 1a: Training Started | B5: 1
A6: Y1: 0-5% of target
A7: Y2: 0-10% of target
A8: Y3: 11-25% of target
A9: Y4: 25-75% of target
A10: Y5: 76-100% of target
A11: GPRA 1b: Training completed | B11: 1
A12: Y1: 0-5% of target
A13: Y2: 0-10% of target
A14: Y3: 11-25% of target
A15: Y4: 25-75% of target
A16: Y5: 76-100% of target
A18: GPRA 2: Placement
A19: GPRA 2a: Placement | B19: 1
A20: Y1: 0-5% of target
A21: Y2: 5-10% of target
A22: Y3: 11-25% of target
A23: Y4: 25-75% of target
A24: Y5: 76-100% of target
A25: GPRA 2b: Placed | B25: 1
A26: Y1: 0-5% of target
A27: Y2: 5-10% of target
A28: Y3: 11-25% of target
A29: Y4: 25-75% of target
A30: Y5: 76-100% of target
A32: GPRA 3: HIRED | B32: 1
A33: Y1: 0-5% of target
A34: Y2: 0-5% of target
A35: Y3: 5-10% of target
A36: Y4: 11-75% of target
A37: Y5: 76-100% of target
B38: =SUM(B5*0.4, B11*0.2, B19*0.1, B25*0.1, B32*0.2) | C38: =SUM(C5*0.4, C11*0.2, C19*0.1, C25*0.1, C32*0.2) | D38: =SUM(D5*0.4, D11*0.2, D19*0.1, D25*0.1, D32*0.2) | E38: =SUM(E5*0.2, E11*0.3, E19*0.2, E25*0.1, E32*0.2) | F38: =SUM(F5*0.2, F11*0.2, F19*0.2, F25*0.2, F32*0.2) | G38: =SUM(G5*0.1, G11*0.1, G19*0.2, G25*0.2, G32*0.4)

Sheet SBMH Substantial Progress
B2: EXAMPLE | C2: Y1 | D2: Y2 | E2: Y3 | F2: Y4 | G2: Y5
A3: Administrative Factors | B3: ='Administrative Factors'!D39 | C3: ='Administrative Factors'!F39 | D3: ='Administrative Factors'!H39 | E3: ='Administrative Factors'!J39 | F3: ='Administrative Factors'!L39 | G3: ='Administrative Factors'!N39
A5: GPRA Measures | B5: ='SBMH- GPRA'!B38 | C5: ='SBMH- GPRA'!D38 | E5: ='SBMH- GPRA'!E38 | F5: ='SBMH- GPRA'!F38 | G5: ='SBMH- GPRA'!G38
A7: TOTAL | B7: =SUM(B3*0.6,B5*0.4) | C7: =SUM(C3*0.6,C5*0.4) | D7: =SUM(D3*0.6,D5*0.4) | E7: =SUM(E3*0.5,E5*0.5) | F7: =SUM(F3*0.5,F5*0.5) | G7: =SUM(G3*0.4,G5*0.6)

Sheet MHSP Substantial Progress
B2: EXAMPLE | C2: Y1 | D2: Y2 | E2: Y3 | F2: Y4 | G2: Y5
A3: Administrative Factors | B3: ='Administrative Factors'!D39 | C3: ='Administrative Factors'!F39 | D3: ='Administrative Factors'!H39 | E3: ='Administrative Factors'!J39 | F3: ='Administrative Factors'!L39 | G3: ='Administrative Factors'!N39
A5: GPRA Measures | B5: ='MHSP - GPRA'!B38 | C5: ='SBMH- GPRA'!D38 | E5: ='SBMH- GPRA'!E38 | F5: ='SBMH- GPRA'!F38 | G5: ='SBMH- GPRA'!G38
A7: TOTAL | B7: =SUM(B3*0.6,B5*0.4) | C7: =SUM(C3*0.6,C5*0.4) | D7: =SUM(D3*0.6,D5*0.4) | E7: =SUM(E3*0.5,E5*0.5) | F7: =SUM(F3*0.5,F5*0.5) | G7: =SUM(G3*0.4,G5*0.6)
